Workbook
Name ExternalData_1: '세중 발권리스트'!$A$1:$BE$19
Name ExternalData_2: '세중 발권리스트'!#REF!
Name ExternalData_3: '세중 발권리스트'!#REF!
Name ExternalData_4: '세중 발권리스트'!#REF!
Name ExternalData_5: '세중 발권리스트'!#REF!
Name ExternalData_6: '세중 발권리스트'!$A$1:$BE$19
Name ExternalData_7: '세중 발권리스트'!$A$1:$BE$13
Name ExternalData_8: '세중 발권리스트'!$A$1:$AZ$30

Sheet CC정리
B2: CC정리
B4: 부서명 | C4: C/C
A5: 51061030 | B5: DB글로벌칩_임원 | C5: B2D102
A6: 51061030 | B6: 영업담당_임원 | C6: B2D311
A7: 51061030 | B7: DDI마케팅파트 | C7: B2D330
A8: 51061030 | B8: 영업팀 | C8: B2D310
A9: 51061030 | B9: 심천지사 | C9: B2D320
A10: 51061030 | B10: SCM담당 | C10: B2D641
A11: 51061030 | B11: 외주생산파트 | C11: B2D340
A12: 51061030 | B12: 전략구매파트 | C12: B2D350
A13: 51061030 | B13: 전략구매파트 | C13: B2D350
A14: 51061030 | B14: 기술지원담당_임원 | C14: B2D201
A15: 51061030 | B15: 품질팀 | C15: B2D710
A16: 71061030 | B16: 제품기술팀 | C16: D2A410
... A33: 71061030 | B33: PMIC개발팀 | C33: D2A790
B34: 전사공통 | C34: B2D100

Sheet 정산내역
B2: ■ 정산내역
B4: 부서명 | C4: C/C | D4: 합계금액
A5: 51061030 | B5: DB글로벌칩_임원 | C5: B2D102 | D5: =SUMIF('e-DAHS 전표내역'!$H:$H,정산내역!C5,'e-DAHS 전표내역'!$U:$U) -> 150000
A6: 51061030 | B6: 영업담당_임원 | C6: B2D311 | D6: =SUMIF('e-DAHS 전표내역'!$H:$H,정산내역!C6,'e-DAHS 전표내역'!$U:$U) -> 0
A7: 51061030 | B7: DDI마케팅파트 | C7: B2D330 | D7: =SUMIF('e-DAHS 전표내역'!$H:$H,정산내역!C7,'e-DAHS 전표내역'!$U:$U) -> 995520
A8: 51061030 | B8: 영업팀 | C8: B2D310 | D8: =SUMIF('e-DAHS 전표내역'!$H:$H,정산내역!C8,'e-DAHS 전표내역'!$U:$U) -> 3475802
A9: 51061030 | B9: 심천지사 | C9: B2D320 | D9: =SUMIF('e-DAHS 전표내역'!$H:$H,정산내역!C9,'e-DAHS 전표내역'!$U:$U) -> 0
A10: 51061030 | B10: SCM담당 | C10: B2D641 | D10: =SUMIF('e-DAHS 전표내역'!$H:$H,정산내역!C10,'e-DAHS 전표내역'!$U:$U) -> 0
A11: 51061030 | B11: 외주생산파트 | C11: B2D340 | D11: =SUMIF('e-DAHS 전표내역'!$H:$H,정산내역!C11,'e-DAHS 전표내역'!$U:$U) -> 0
A12: 51061030 | B12: 전략구매파트 | C12: B2D350 | D12: =SUMIF('e-DAHS 전표내역'!$H:$H,정산내역!C12,'e-DAHS 전표내역'!$U:$U) -> 0
A13: 51061030 | B13: 전략구매파트 | C13: B2D350 | D13: =SUMIF('e-DAHS 전표내역'!$H:$H,정산내역!C13,'e-DAHS 전표내역'!$U:$U) -> 0
A14: 51061030 | B14: 기술지원담당_임원 | C14: B2D201 | D14: =SUMIF('e-DAHS 전표내역'!$H:$H,정산내역!C14,'e-DAHS 전표내역'!$U:$U) -> 0
A15: 51061030 | B15: 품질팀 | C15: B2D710 | D15: =SUMIF('e-DAHS 전표내역'!$H:$H,정산내역!C15,'e-DAHS 전표내역'!$U:$U) -> 0
A16: 71061030 | B16: 제품기술팀 | C16: D2A410 | D16: =SUMIF('e-DAHS 전표내역'!$H:$H,정산내역!C16,'e-DAHS 전표내역'!$U:$U) -> 862770
... A26: 71061030 | B26: PMIC개발팀 | C26: D2A790 | D26: =SUMIF('e-DAHS 전표내역'!$H:$H,정산내역!C26,'e-DAHS 전표내역'!$U:$U) -> 0
B27: 전사공통 | C27: B2D100 | D27: =SUMIF('e-DAHS 전표내역'!$H:$H,정산내역!C27,'e-DAHS 전표내역'!$U:$U) -> 0
B28: 합계금액 | D28: =SUM(D5:D27) -> 16719800
B30: ■ 기타사항
B31: -4/20(월) 변동사항 없음

Sheet e-DAHS 전표내역
A1: 선택 | B1: 구분 | D1: 승인번호 | E1: 이용자명(영문) | F1: 이용자명(국문) | G1: 부서명 | H1: 부서코드 | I1: 출발일자 | J1: 여정 | K1: 법인 | L1: 카드사 | M1: 카드번호 | N1: 사용일자 | O1: 상호 | P1: 업종 | Q1: 통화 | R1: 공급가액 | S1: 부가세 | T1: 봉사료 | U1: 합계 | V1: 지급일 | W1: 출장 문서번호 | X1: 전표번호
B3: 매입 | C3: 신규 | D3: 20603304 | E3: LEE/SANGTAE | F3: =VLOOKUP(E3,영문국문명!$D$2:$F$252,2,0) -> 이상태 | G3: =VLOOKUP(E3,영문국문명!$D$2:$F$252,3,0) -> 영업팀 | H3: =VLOOKUP(G3,CC정리!$B$5:$C$34,2,0) -> B2D310 | I3: 20260413 | J3: ICN/SZX/ICN | K3: 7018802701 (주)DB글로벌칩 | L3: 하나은행 | M3: 4336-9200-****-1581 | N3: 2026-04-06 | O3: 대한항공주식회사BSP | P3: 대한항공 | Q3: KRW | R3: 1206800 | S3: 0 | T3: 0 | U3: 1206800 | V3: 2026-04-25
B4: 매입 | C4: 신규 | D4: 21603304 | E4: LEE/SANGTAE | F4: =VLOOKUP(E4,영문국문명!$D$2:$F$252,2,0) -> 이상태 | G4: =VLOOKUP(E4,영문국문명!$D$2:$F$252,3,0) -> 영업팀 | H4: =VLOOKUP(G4,CC정리!$B$5:$C$34,2,0) -> B2D310 | I4: 20260413 | J4: ICN/SZX/ICN | K4: 7018802701 (주)DB글로벌칩 | L4: 하나은행 | M4: 4336-9200-****-1581 | N4: 2026-04-06 | O4: 이니시스_취급수수료 | P4: 여행사 | Q4: KRW | R4: 44303 | S4: 0 | T4: 0 | U4: 44303 | V4: 2026-04-25
B5: 매입 | C5: 신규 | D5: 11602804 | E5: PARK/JEONGTAE | F5: =VLOOKUP(E5,영문국문명!$D$2:$F$252,2,0) -> #N/A | G5: =VLOOKUP(E5,영문국문명!$D$2:$F$252,3,0) -> #N/A | H5: =VLOOKUP(G5,CC정리!$B$5:$C$34,2,0) -> #N/A | I5: 20260408 | J5: ICN/TPE/ICN | K5: 7018802701 (주)DB글로벌칩 | L5: 하나은행 | M5: 4336-9200-****-1581 | N5: 2026-04-01 | O5: 대한항공주식회사BSP | P5: 대한항공 | Q5: KRW | R5: 643800 | S5: 0 | T5: 0 | U5: 643800 | V5: 2026-04-25
B6: 매입 | C6: 신규 | D6: 13602804 | E6: KIM/HEEJIN | F6: =VLOOKUP(E6,영문국문명!$D$2:$F$252,2,0) -> 김희진 | G6: =VLOOKUP(E6,영문국문명!$D$2:$F$252,3,0) -> PKG파트 | H6: =VLOOKUP(G6,CC정리!$B$5:$C$34,2,0) -> B2D800 | I6: 20260408 | J6: ICN/TPE/ICN | K6: 7018802701 (주)DB글로벌칩 | L6: 하나은행 | M6: 4336-9200-****-1581 | N6: 2026-04-01 | O6: 대한항공주식회사BSP | P6: 대한항공 | Q6: KRW | R6: 643800 | S6: 0 | T6: 0 | U6: 643800 | V6: 2026-04-25
B7: 매입 | C7: 신규 | D7: 14602804 | E7: KIM/HEEJIN | F7: =VLOOKUP(E7,영문국문명!$D$2:$F$252,2,0) -> 김희진 | G7: =VLOOKUP(E7,영문국문명!$D$2:$F$252,3,0) -> PKG파트 | H7: =VLOOKUP(G7,CC정리!$B$5:$C$34,2,0) -> B2D800 | I7: 20260408 | J7: ICN/TPE/ICN | K7: 7018802701 (주)DB글로벌칩 | L7: 하나은행 | M7: 4336-9200-****-1581 | N7: 2026-04-01 | O7: 이니시스_취급수수료 | P7: 여행사 | Q7: KRW | R7: 24380 | S7: 0 | T7: 0 | U7: 24380 | V7: 2026-04-25
B8: 매입 | C8: 신규 | D8: 15602804 | E8: LEE/JONGRAE | F8: =VLOOKUP(E8,영문국문명!$D$2:$F$252,2,0) -> #N/A | G8: =VLOOKUP(E8,영문국문명!$D$2:$F$252,3,0) -> #N/A | H8: =VLOOKUP(G8,CC정리!$B$5:$C$34,2,0) -> #N/A | I8: 20260408 | J8: ICN/TPE/ICN | K8: 7018802701 (주)DB글로벌칩 | L8: 하나은행 | M8: 4336-9200-****-1581 | N8: 2026-04-01 | O8: 이니시스_취급수수료 | P8: 여행사 | Q8: KRW | R8: 24380 | S8: 0 | T8: 0 | U8: 24380 | V8: 2026-04-25
B9: 매입 | C9: 신규 | D9: 16602804 | E9: PARK/JEONGTAE | F9: =VLOOKUP(E9,영문국문명!$D$2:$F$252,2,0) -> #N/A | G9: =VLOOKUP(E9,영문국문명!$D$2:$F$252,3,0) -> #N/A | H9: =VLOOKUP(G9,CC정리!$B$5:$C$34,2,0) -> #N/A | I9: 20260408 | J9: ICN/TPE/ICN | K9: 7018802701 (주)DB글로벌칩 | L9: 하나은행 | M9: 4336-9200-****-1581 | N9: 2026-04-01 | O9: 이니시스_취급수수료 | P9: 여행사 | Q9: KRW | R9: 24380 | S9: 0 | T9: 0 | U9: 24380 | V9: 2026-04-25
B10: 매입 | C10: 신규 | D10: 17602804 | E10: JEONG/YEONHO | F10: =VLOOKUP(E10,영문국문명!$D$2:$F$252,2,0) -> #N/A | G10: =VLOOKUP(E10,영문국문명!$D$2:$F$252,3,0) -> #N/A | H10: =VLOOKUP(G10,CC정리!$B$5:$C$34,2,0) -> #N/A | I10: 20260402 | J10: SZX/ICN | K10: 7018802701 (주)DB글로벌칩 | L10: 하나은행 | M10: 4336-9200-****-1581 | N10: 2026-04-01 | O10: (주)세중 | P10: 여행사 | Q10: KRW | R10: 192600 | S10: 0 | T10: 0 | U10: 192600 | V10: 2026-04-25
B11: 매입 | C11: 신규 | D11: 18602804 | E11: JEONG/HOYONG | F11: =VLOOKUP(E11,영문국문명!$D$2:$F$252,2,0) -> #N/A | G11: =VLOOKUP(E11,영문국문명!$D$2:$F$252,3,0) -> #N/A | H11: =VLOOKUP(G11,CC정리!$B$5:$C$34,2,0) -> #N/A | I11: 20260402 | J11: SZX/ICN | K11: 7018802701 (주)DB글로벌칩 | L11: 하나은행 | M11: 4336-9200-****-1581 | N11: 2026-04-01 | O11: (주)세중 | P11: 여행사 | Q11: KRW | R11: 192600 | S11: 0 | T11: 0 | U11: 192600 | V11: 2026-04-25
B12: 매입 | C12: 신규 | D12: 19601804 | E12: LEE/JONGRAE | F12: =VLOOKUP(E12,영문국문명!$D$2:$F$252,2,0) -> #N/A | G12: =VLOOKUP(E12,영문국문명!$D$2:$F$252,3,0) -> #N/A | H12: =VLOOKUP(G12,CC정리!$B$5:$C$34,2,0) -> #N/A | I12: 20260408 | J12: ICN/TPE/ICN | K12: 7018802701 (주)DB글로벌칩 | L12: 하나은행 | M12: 4336-9200-****-1581 | N12: 2026-04-01 | O12: 대한항공주식회사BSP | P12: 대한항공 | Q12: KRW | R12: 643800 | S12: 0 | T12: 0 | U12: 643800 | V12: 2026-04-25
B13: 매입 | C13: 신규 | D13: 10601704 | E13: JEONG/HOYONG | F13: =VLOOKUP(E13,영문국문명!$D$2:$F$252,2,0) -> #N/A | G13: =VLOOKUP(E13,영문국문명!$D$2:$F$252,3,0) -> #N/A | H13: =VLOOKUP(G13,CC정리!$B$5:$C$34,2,0) -> #N/A | I13: 20260504 | J13: ICN/LAX/ICN | K13: 7018802701 (주)DB글로벌칩 | L13: 하나은행 | M13: 4336-9200-****-1581 | N13: 2026-03-31 | O13: 대한항공주식회사BSP | P13: 대한항공 | Q13: KRW | R13: 2186700 | S13: 0 | T13: 0 | U13: 2186700 | V13: 2026-04-25
B14: 매입 | C14: 신규 | D14: 12601704 | E14: KO/JAEHONG | F14: =VLOOKUP(E14,영문국문명!$D$2:$F$252,2,0) -> 고재홍 | G14: =VLOOKUP(E14,영문국문명!$D$2:$F$252,3,0) -> DDI개발담당_임원 | H14: =VLOOKUP(G14,CC정리!$B$5:$C$34,2,0) -> D2A701 | I14: 20260504 | J14: ICN/LAX/ICN | K14: 7018802701 (주)DB글로벌칩 | L14: 하나은행 | M14: 4336-9200-****-1581 | N14: 2026-03-31 | O14: 대한항공주식회사BSP | P14: 대한항공 | Q14: KRW | R14: 7620200 | S14: 0 | T14: 0 | U14: 7620200 | V14: 2026-04-25
... B62: 매입 | C62: 신규 | D62: 6606203 | E62: LEE/JUNMIN | F62: =VLOOKUP(E62,영문국문명!$D$2:$F$252,2,0) -> 이준민 | G62: =VLOOKUP(E62,영문국문명!$D$2:$F$252,3,0) -> Analog1파트 | H62: =VLOOKUP(G62,CC정리!$B$5:$C$34,2,0) -> D2A830 | I62: 20260331 | J62: ICN/CKG/ICN | K62: 7018802701 (주)DB글로벌칩 | L62: 하나은행 | M62: 4336-9200-****-1581 | N62: 2026-03-16 | O62: 이니시스_취급수수료 | P62: 여행사 | Q62: KRW | R62: 19668 | S62: 0 | T62: 0 | U62: 19668 | V62: 2026-04-25
U63: =SUM(U3:U62) -> 25858214

Sheet 세중 발권리스트
A1: 순번 | B1: 항공사 | C1: 항공권번호 | D1: CJ NO | E1: 판매 | F1: 지사 | G1: 발권일자 | H1: 항공사명 | I1: 코드 | J1: 고객사명 | K1: 고객명 | L1: 고객명(영문) | M1: 고객사번 | N1: 생년월일 | O1: 영업사원 | P1: 발권사원 | Q1: 단체 | R1: 번호 | S1: 출발일 | T1: 도시 | U1: 도시(한글) | V1: GDS구분 | W1: 목적 지역명 | X1: 목적 국가 | Y1: 목적 국가명 | Z1: 목적 도시 | AA1: 목적 도시명 | AB1: 카드번호 | AC1: 승인번호 | AD1: Fare Amt | AE1: Tax Amt | AF1: Fuel Amt | AG1: Dc Amt | AH1: Net Amt | AI1: Card Amt | AJ1: Cash Amt | AK1: Cc Amt | AL1: Com Amt | AM1: 환불금액 | AN1: 환불 (FARE) | AO1: 환불 (TAX) | AP1: 환불일자 | AQ1: 환불구분 | AR1: 수수료률 | AS1: CANCLE_AMT | AT1: 취급수수료총액 | AU1: 취급수수료 | AV1: 취급승인번호 | AW1: 승인일자 | AX1: 부가세 | AY1: 재발행항공권 | AZ1: 발권구분
A2: 6 | B2: 999 | C2: 5018954423 | D2: - - | E2: N | F2: 본사 | G2: 20260316 | H2: CA | I2: K04709 | J2: 주식회사 디비하이텍 | L2: OH/TAKJUN | N2: / / | O2: 박지운 | P2: 한연지 | S2: 20260331 | T2: ICN/CKG/ICN | U2: 인천/충칭(중경)/인천 | V2: AMADEUS | W2: 중국 | X2: CHN | Y2: 중국 | Z2: CKG | AA2: 충칭(중경) | AB2: VI433692******1581 | AC2: 01606203 | AD2: 447000 | AE2: 94100 | AF2: 50600 | AG2: 0 | AH2: 541100 | AI2: 541100 | AJ2: 0 | AK2: 541100 | AL2: 13410 | AM2: 0 | AN2: 0 | AO2: 0 | AP2: / / | AR2: 4 | AS2: 0 | AT2: 19668 | AU2: 17880 | AV2: 02606203 | AW2: 2026/03/16 | AX2: 1788 | AY2: - - | AZ2: 신규발행
A3: 7 | B3: 999 | C3: 5018954425 | D3: - - | E3: N | F3: 본사 | G3: 20260316 | H3: CA | I3: K04709 | J3: 주식회사 디비하이텍 | L3: JUNG/CHANKYEONG | N3: / / | O3: 박지운 | P3: 한연지 | S3: 20260331 | T3: ICN/CKG/ICN | U3: 인천/충칭(중경)/인천 | V3: AMADEUS | W3: 중국 | X3: CHN | Y3: 중국 | Z3: CKG | AA3: 충칭(중경) | AB3: VI433692******1581 | AC3: 03606203 | AD3: 447000 | AE3: 94100 | AF3: 50600 | AG3: 0 | AH3: 541100 | AI3: 541100 | AJ3: 0 | AK3: 541100 | AL3: 13410 | AM3: 0 | AN3: 0 | AO3: 0 | AP3: / / | AR3: 4 | AS3: 0 | AT3: 19668 | AU3: 17880 | AV3: 04606203 | AW3: 2026/03/16 | AX3: 1788 | AY3: - - | AZ3: 신규발행
A4: 8 | B4: 999 | C4: 5018954426 | D4: - - | E4: N | F4: 본사 | G4: 20260316 | H4: CA | I4: K04709 | J4: 주식회사 디비하이텍 | L4: LEE/JUNMIN | N4: / / | O4: 박지운 | P4: 한연지 | S4: 20260331 | T4: ICN/CKG/ICN | U4: 인천/충칭(중경)/인천 | V4: AMADEUS | W4: 중국 | X4: CHN | Y4: 중국 | Z4: CKG | AA4: 충칭(중경) | AB4: VI433692******1581 | AC4: 05606203 | AD4: 447000 | AE4: 94100 | AF4: 50600 | AG4: 0 | AH4: 541100 | AI4: 541100 | AJ4: 0 | AK4: 541100 | AL4: 13410 | AM4: 0 | AN4: 0 | AO4: 0 | AP4: / / | AR4: 4 | AS4: 0 | AT4: 19668 | AU4: 17880 | AV4: 06606203 | AW4: 2026/03/16 | AX4: 1788 | AY4: - - | AZ4: 신규발행
A5: 9 | B5: 180 | C5: 5018985483 | D5: - - | E5: N | F5: 본사 | G5: 20260317 | H5: KE | I5: K04709 | J5: 주식회사 디비하이텍 | K5: 정겨운 | L5: JUNG/KYUWOON | N5: 1992/07/20 | O5: 박지운 | P5: 한연지 | S5: 20260323 | T5: GMP/SHA/SZX/ICN | U5: 서울/상하이(상해)/심천/인천 | V5: AMADEUS | W5: 중국 | X5: CHN | Y5: 중국 | Z5: SHA | AA5: 상하이(상해) | AB5: VI433692******1581 | AC5: 08606303 | AD5: 873900 | AE5: 90300 | AF5: 46500 | AG5: 0 | AH5: 964200 | AI5: 964200 | AJ5: 0 | AK5: 964200 | AL5: 0 | AM5: 0 | AN5: 0 | AO5: 0 | AP5: / / | AR5: 4 | AS5: 0 | AT5: 38451 | AU5: 34960 | AV5: 09606303 | AW5: 2026/03/17 | AX5: 3491 | AY5: - - | AZ5: 신규발행
A6: 12 | B6: 781 | C6: 5019046044 | D6: - - | E6: N | F6: 본사 | G6: 20260319 | H6: MU | I6: K04709 | J6: 주식회사 디비하이텍 | K6: 정겨운 | L6: JUNG/KYUWOON | N6: 1992/07/20 | O6: 박지운 | P6: 한연지 | S6: 20260325 | T6: SHA/SZX | U6: 상하이(상해)/심천 | V6: AMADEUS | W6: 중국 | X6: CHN | Y6: 중국 | Z6: SHA | AA6: 상하이(상해) | AB6: VI433692******1581 | AC6: 00607503 | AD6: 481000 | AE6: 15200 | AF6: 4400 | AG6: 0 | AH6: 496200 | AI6: 496200 | AJ6: 0 | AK6: 496200 | AL6: 0 | AM6: 0 | AN6: 0 | AO6: 0 | AP6: / / | AR6: 4 | AS6: 0 | AT6: 21164 | AU6: 19240 | AV6: 01607503 | AW6: 2026/03/19 | AX6: 1924 | AY6: - - | AZ6: SOTO(0%)
A7: 13 | B7: 781 | C7: 5019090441 | D7: - - | E7: N | F7: 본사 | G7: 20260320 | H7: MU | I7: K04709 | J7: 주식회사 디비하이텍 | K7: 정겨운 | L7: JUNG/KYUWOON | N7: 1992/07/20 | O7: 박지운 | P7: 한연지 | S7: 20260324 | T7: SHA/SZX | U7: 상하이(상해)/심천 | V7: AMADEUS | W7: 중국 | X7: CHN | Y7: 중국 | Z7: SHA | AA7: 상하이(상해) | AB7: VI433692******1581 | AC7: 02607603 | AD7: 0 | AE7: 24400 | AF7: 0 | AG7: 0 | AH7: 24400 | AI7: 24400 | AJ7: 0 | AK7: 24400 | AL7: 0 | AM7: 0 | AN7: 0 | AO7: 0 | AP7: / / | AR7: 0 | AS7: 0 | AT7: 0 | AU7: 0 | AX7: 0 | AY7: 5019-046-044 | AZ7: 신규발행
A8: 14 | B8: 999 | C8: 5019090458 | D8: - - | E8: N | F8: 본사 | G8: 20260320 | H8: CA | I8: K04709 | J8: 주식회사 디비하이텍 | K8: 김형호 | L8: KIM/HYEONGHO | N8: 1988/07/14 | O8: 박지운 | P8: 한연지 | S8: 20260323 | T8: ICN/CKG/ICN | U8: 인천/충칭(중경)/인천 | V8: AMADEUS | W8: 중국 | X8: CHN | Y8: 중국 | Z8: CKG | AA8: 충칭(중경) | AB8: VI433692******1581 | AC8: 03607603 | AD8: 561000 | AE8: 94600 | AF8: 51000 | AG8: 0 | AH8: 655600 | AI8: 655600 | AJ8: 0 | AK8: 655600 | AL8: 0 | AM8: 0 | AN8: 0 | AO8: 0 | AP8: / / | AR8: 4 | AS8: 0 | AT8: 24684 | AU8: 22440 | AV8: 04607603 | AW8: 2026/03/20 | AX8: 2244 | AY8: - - | AZ8: 신규발행
A9: 19 | B9: 479 | C9: 5460152825 | D9: - - | E9: N | F9: 본사 | G9: 20260326 | H9: ZH | I9: K04709 | J9: 주식회사 디비하이텍 | L9: JEONG/YEONHO | N9: / / | O9: 박지운 | P9: 한연지 | S9: 20260401 | T9: SZX/ICN | U9: 심천/인천 | V9: AMADEUS | W9: 중국 | X9: CHN | Y9: 중국 | Z9: SZX | AA9: 심천 | AB9: VI433692******1581 | AC9: 11608203 | AD9: 642000 | AE9: 69200 | AF9: 49600 | AG9: 0 | AH9: 711200 | AI9: 0 | AJ9: 711200 | AK9: 0 | AL9: 0 | AM9: 0 | AN9: 0 | AO9: 0 | AP9: / / | AR9: 4 | AS9: 0 | AT9: 28248 | AU9: 25680 | AV9: 19607203 | AW9: 2026/03/26 | AX9: 2568 | AY9: - - | AZ9: PTA(0%)
A10: 20 | B10: 479 | C10: 5460152826 | D10: - - | E10: N | F10: 본사 | G10: 20260326 | H10: ZH | I10: K04709 | J10: 주식회사 디비하이텍 | L10: JEONG/HOYONG | N10: / / | O10: 박지운 | P10: 한연지 | S10: 20260401 | T10: SZX/ICN | U10: 심천/인천 | V10: AMADEUS | W10: 중국 | X10: CHN | Y10: 중국 | Z10: SZX | AA10: 심천 | AB10: VI433692******1581 | AC10: 12608203 | AD10: 642000 | AE10: 69200 | AF10: 49600 | AG10: 0 | AH10: 711200 | AI10: 0 | AJ10: 711200 | AK10: 0 | AL10: 0 | AM10: 0 | AN10: 0 | AO10: 0 | AP10: / / | AR10: 4 | AS10: 0 | AT10: 28248 | AU10: 25680 | AV10: 10608203 | AW10: 2026/03/26 | AX10: 2568 | AY10: - - | AZ10: PTA(0%)
A11: 21 | B11: 988 | C11: 9490109815 | D11: - - | E11: N | F11: 본사 | G11: 20260326 | H11: OZ | I11: K04709 | J11: 주식회사 디비하이텍 | L11: JEONG/YEONHO | N11: / / | O11: 박지운 | P11: 한연지 | S11: 20260330 | T11: ICN/SZX | U11: 인천/심천 | V11: ABACUS | W11: 중국 | X11: CHN | Y11: 중국 | Z11: SZX | AA11: 심천 | AB11: VI433692******1581 | AC11: 15607203 | AD11: 400000 | AE11: 51700 | AF11: 27700 | AG11: 0 | AH11: 451700 | AI11: 451700 | AJ11: 0 | AK11: 451700 | AL11: 0 | AM11: 0 | AN11: 0 | AO11: 0 | AP11: / / | AR11: 4 | AS11: 0 | AT11: 17600 | AU11: 16000 | AV11: 16607203 | AW11: 2026/03/26 | AX11: 1600 | AY11: - - | AZ11: 신규발행
A12: 22 | B12: 988 | C12: 9490109816 | D12: - - | E12: N | F12: 본사 | G12: 20260326 | H12: OZ | I12: K04709 | J12: 주식회사 디비하이텍 | L12: JEONG/HOYONG | N12: / / | O12: 박지운 | P12: 한연지 | S12: 20260330 | T12: ICN/SZX | U12: 인천/심천 | V12: ABACUS | W12: 중국 | X12: CHN | Y12: 중국 | Z12: SZX | AA12: 심천 | AB12: VI433692******1581 | AC12: 17607203 | AD12: 400000 | AE12: 51700 | AF12: 27700 | AG12: 0 | AH12: 451700 | AI12: 451700 | AJ12: 0 | AK12: 451700 | AL12: 0 | AM12: 0 | AN12: 0 | AO12: 0 | AP12: / / | AR12: 4 | AS12: 0 | AT12: 17600 | AU12: 16000 | AV12: 18607203 | AW12: 2026/03/26 | AX12: 1600 | AY12: - - | AZ12: 신규발행
A13: 23 | B13: 180 | C13: 5460197811 | D13: - - | E13: N | F13: 본사 | G13: 20260327 | H13: KE | I13: K04709 | J13: 주식회사 디비하이텍 | L13: KO/JAEHONG | N13: / / | O13: 박지운 | P13: 한연지 | S13: 20260407 | T13: ICN/WUH/ICN | U13: 인천/우한(무한)/인천 | V13: AMADEUS | W13: 중국 | X13: CHN | Y13: 중국 | Z13: WUH | AA13: 우한(무한) | AB13: VI433692******1581 | AC13: 14608303 | AD13: 680000 | AE13: 85600 | AF13: 42000 | AG13: 0 | AH13: 765600 | AI13: 765600 | AJ13: 0 | AK13: 765600 | AL13: 0 | AM13: 0 | AN13: 0 | AO13: 0 | AP13: / / | AR13: 4 | AS13: 0 | AT13: 29920 | AU13: 27200 | AV13: 15609303 | AW13: 2026/03/27 | AX13: 2720 | AY13: - - | AZ13: 신규발행
A14: 24 | B14: 180 | C14: 5460197812 | D14: - - | E14: N | F14: 본사 | G14: 20260327 | H14: KE | I14: K04709 | J14: 주식회사 디비하이텍 | K14: 최상신 | L14: CHOI/SANGSHIN | N14: 1972/10/06 | O14: 박지운 | P14: 한연지 | S14: 20260407 | T14: ICN/WUH/ICN | U14: 인천/우한(무한)/인천 | V14: AMADEUS | W14: 중국 | X14: CHN | Y14: 중국 | Z14: WUH | AA14: 우한(무한) | AB14: VI433692******1581 | AC14: 16608303 | AD14: 680000 | AE14: 85600 | AF14: 42000 | AG14: 0 | AH14: 765600 | AI14: 765600 | AJ14: 0 | AK14: 765600 | AL14: 0 | AM14: 0 | AN14: 0 | AO14: 0 | AP14: / / | AR14: 4 | AS14: 0 | AT14: 29920 | AU14: 27200 | AV14: 16609303 | AW14: 2026/03/27 | AX14: 2720 | AY14: - - | AZ14: 신규발행
A15: 25 | B15: 180 | C15: 5460197813 | D15: - - | E15: N | F15: 본사 | G15: 20260327 | H15: KE | I15: K04709 | J15: 주식회사 디비하이텍 | L15: PARK/SANGHYUN | N15: / / | O15: 박지운 | P15: 한연지 | S15: 20260407 | T15: ICN/WUH/ICN | U15: 인천/우한(무한)/인천 | V15: AMADEUS | W15: 중국 | X15: CHN | Y15: 중국 | Z15: WUH | AA15: 우한(무한) | AB15: VI433692******1581 | AC15: 18608303 | AD15: 680000 | AE15: 85600 | AF15: 42000 | AG15: 0 | AH15: 765600 | AI15: 765600 | AJ15: 0 | AK15: 765600 | AL15: 0 | AM15: 0 | AN15: 0 | AO15: 0 | AP15: / / | AR15: 4 | AS15: 0 | AT15: 29920 | AU15: 27200 | AV15: 17609303 | AW15: 2026/03/27 | AX15: 2720 | AY15: - - | AZ15: 신규발행
A16: 26 | B16: 180 | C16: 5460197814 | D16: - - | E16: N | F16: 본사 | G16: 20260327 | H16: KE | I16: K04709 | J16: 주식회사 디비하이텍 | K16: 김기일 | L16: KIM/KIIL | N16: 1983/07/08 | O16: 박지운 | P16: 한연지 | S16: 20260407 | T16: ICN/WUH/ICN | U16: 인천/우한(무한)/인천 | V16: AMADEUS | W16: 중국 | X16: CHN | Y16: 중국 | Z16: WUH | AA16: 우한(무한) | AB16: VI433692******1581 | AC16: 10609303 | AD16: 680000 | AE16: 85600 | AF16: 42000 | AG16: 0 | AH16: 765600 | AI16: 765600 | AJ16: 0 | AK16: 765600 | AL16: 0 | AM16: 0 | AN16: 0 | AO16: 0 | AP16: / / | AR16: 4 | AS16: 0 | AT16: 29920 | AU16: 27200 | AV16: 18609303 | AW16: 2026/03/27 | AX16: 2720 | AY16: - - | AZ16: 신규발행
A17: 27 | B17: 180 | C17: 5460197815 | D17: - - | E17: N | F17: 본사 | G17: 20260327 | H17: KE | I17: K04709 | J17: 주식회사 디비하이텍 | K17: 변승찬 | L17: BYUN/SEUNGCHAN | N17: 1977/02/13 | O17: 박지운 | P17: 한연지 | S17: 20260407 | T17: ICN/WUH/ICN | U17: 인천/우한(무한)/인천 | V17: AMADEUS | W17: 중국 | X17: CHN | Y17: 중국 | Z17: WUH | AA17: 우한(무한) | AB17: VI433692******1581 | AC17: 12609303 | AD17: 680000 | AE17: 85600 | AF17: 42000 | AG17: 0 | AH17: 765600 | AI17: 765600 | AJ17: 0 | AK17: 765600 | AL17: 0 | AM17: 0 | AN17: 0 | AO17: 0 | AP17: / / | AR17: 4 | AS17: 0 | AT17: 29920 | AU17: 27200 | AV17: 19609303 | AW17: 2026/03/27 | AX17: 2720 | AY17: - - | AZ17: 신규발행
A18: 28 | B18: 180 | C18: 5460197816 | D18: - - | E18: N | F18: 본사 | G18: 20260327 | H18: KE | I18: K04709 | J18: 주식회사 디비하이텍 | L18: HWANG/DAEWOOK | N18: / / | O18: 박지운 | P18: 한연지 | S18: 20260407 | T18: ICN/WUH/ICN | U18: 인천/우한(무한)/인천 | V18: AMADEUS | W18: 중국 | X18: CHN | Y18: 중국 | Z18: WUH | AA18: 우한(무한) | AB18: VI433692******1581 | AC18: 14609303 | AD18: 680000 | AE18: 85600 | AF18: 42000 | AG18: 0 | AH18: 765600 | AI18: 765600 | AJ18: 0 | AK18: 765600 | AL18: 0 | AM18: 0 | AN18: 0 | AO18: 0 | AP18: / / | AR18: 4 | AS18: 0 | AT18: 29920 | AU18: 27200 | AV18: 10600304 | AW18: 2026/03/27 | AX18: 2720 | AY18: - - | AZ18: 신규발행
A19: 34 | B19: 180 | C19: 5460268658 | D19: - - | E19: N | F19: 본사 | G19: 20260330 | H19: KE | I19: K04709 | J19: 주식회사 디비하이텍 | L19: PARK/CHANHO | N19: / / | O19: 박지운 | P19: 한연지 | S19: 20260503 | T19: ICN/LAX/ICN | U19: 인천/로스앤젤레스/인천 | V19: AMADEUS | W19: 북미 | X19: USA | Y19: 미국 | Z19: LAX | AA19: 로스앤젤레스 | AB19: VI433692******1581 | AC19: 12600604 | AD19: 7323500 | AE19: 296500 | AF19: 159000 | AG19: 0 | AH19: 7620000 | AI19: 7620000 | AJ19: 0 | AK19: 7620000 | AL19: 0 | AM19: 7470000 | AN19: 7323500 | AO19: 296500 | AP19: 2026/04/09 | AQ19: 전체환불 | AR19: 4 | AS19: 150000 | AT19: 322234 | AU19: 292940 | AV19: 13600604 | AW19: 2026/03/30 | AX19: 29294 | AY19: - - | AZ19: 신규발행
A20: 36 | B20: 180 | C20: 5460330185 | D20: - - | E20: N | F20: 본사 | G20: 20260330 | H20: KE | I20: K04709 | J20: 주식회사 디비하이텍 | K20: 윤추실 | L20: YIN/QIUSHI | N20: 1996/11/13 | O20: 박지운 | P20: 한연지 | S20: 20260331 | T20: ICN/CAN/ICN | U20: 인천/광저우(광주)/인천 | V20: AMADEUS | W20: 중국 | X20: CHN | Y20: 중국 | Z20: CAN | AA20: 광저우(광주) | AB20: VI433692******1581 | AC20: 15600604 | AD20: 735700 | AE20: 94700 | AF20: 51000 | AG20: 0 | AH20: 830400 | AI20: 830400 | AJ20: 0 | AK20: 830400 | AL20: 0 | AM20: 0 | AN20: 0 | AO20: 0 | AP20: / / | AR20: 4 | AS20: 0 | AT20: 32370 | AU20: 29430 | AV20: 16600604 | AW20: 2026/03/30 | AX20: 2940 | AY20: - - | AZ20: 신규발행
A21: 37 | B21: 180 | C21: 5460357604 | D21: - - | E21: N | F21: 본사 | G21: 20260331 | H21: KE | I21: K04709 | J21: 주식회사 디비하이텍 | L21: KO/JAEHONG | N21: / / | O21: 박지운 | P21: 한연지 | S21: 20260504 | T21: ICN/LAX/ICN | U21: 인천/로스앤젤레스/인천 | V21: AMADEUS | W21: 북미 | X21: USA | Y21: 미국 | Z21: LAX | AA21: 로스앤젤레스 | AB21: VI433692******1581 | AC21: 12601704 | AD21: 7323500 | AE21: 296700 | AF21: 159000 | AG21: 0 | AH21: 7620200 | AI21: 7620200 | AJ21: 0 | AK21: 7620200 | AL21: 0 | AM21: 7470200 | AN21: 7323500 | AO21: 296700 | AP21: 2026/04/10 | AQ21: 전체환불 | AR21: 4 | AS21: 150000 | AT21: 322234 | AU21: 292940 | AV21: 13601704 | AW21: 2026/03/31 | AX21: 29294 | AY21: - - | AZ21: 신규발행
A22: 38 | B22: 180 | C22: 5460357606 | D22: - - | E22: N | F22: 본사 | G22: 20260331 | H22: KE | I22: K04709 | J22: 주식회사 디비하이텍 | K22: 홍형도 | L22: HONG/HYOUNGDO | N22: 1984/08/26 | O22: 박지운 | P22: 한연지 | S22: 20260504 | T22: ICN/LAX/ICN | U22: 인천/로스앤젤레스/인천 | V22: AMADEUS | W22: 북미 | X22: USA | Y22: 미국 | Z22: LAX | AA22: 로스앤젤레스 | AB22: VI433692******1581 | AC22: 18600704 | AD22: 1890000 | AE22: 296700 | AF22: 159000 | AG22: 0 | AH22: 2186700 | AI22: 2186700 | AJ22: 0 | AK22: 2186700 | AL22: 0 | AM22: 1986700 | AN22: 1890000 | AO22: 296700 | AP22: 2026/04/09 | AQ22: 전체환불 | AR22: 4 | AS22: 200000 | AT22: 83160 | AU22: 75600 | AV22: 14601704 | AW22: 2026/03/31 | AX22: 7560 | AY22: - - | AZ22: 신규발행
A23: 39 | B23: 180 | C23: 5460357607 | D23: - - | E23: N | F23: 본사 | G23: 20260331 | H23: KE | I23: K04709 | J23: 주식회사 디비하이텍 | L23: JEONG/HOYONG | N23: / / | O23: 박지운 | P23: 한연지 | S23: 20260504 | T23: ICN/LAX/ICN | U23: 인천/로스앤젤레스/인천 | V23: AMADEUS | W23: 북미 | X23: USA | Y23: 미국 | Z23: LAX | AA23: 로스앤젤레스 | AB23: VI433692******1581 | AC23: 10601704 | AD23: 1890000 | AE23: 296700 | AF23: 159000 | AG23: 0 | AH23: 2186700 | AI23: 2186700 | AJ23: 0 | AK23: 2186700 | AL23: 0 | AM23: 0 | AN23: 0 | AO23: 0 | AP23: / / | AR23: 4 | AS23: 0 | AT23: 83160 | AU23: 75600 | AV23: 15601704 | AW23: 2026/03/31 | AX23: 7560 | AY23: - - | AZ23: 신규발행
A24: 40 | B24: 479 | C24: 5460399646 | D24: - - | E24: N | F24: 본사 | G24: 20260331 | H24: ZH | I24: K04709 | J24: 주식회사 디비하이텍 | L24: JEONG/YEONHO | N24: / / | O24: 박지운 | P24: 한연지 | S24: 20260402 | T24: SZX/ICN | U24: 심천/인천 | V24: AMADEUS | W24: 중국 | X24: CHN | Y24: 중국 | Z24: SZX | AA24: 심천 | AB24: VI433692******1581 | AC24: 17602804 | AD24: 192300 | AE24: 300 | AF24: 200 | AG24: 0 | AH24: 192600 | AI24: 0 | AJ24: 192600 | AK24: 0 | AL24: 0 | AM24: 0 | AN24: 0 | AO24: 0 | AP24: / / | AR24: 4 | AS24: 0 | AT24: 8461 | AU24: 7690 | AV24: 16601704 | AW24: 2026/03/31 | AX24: 771 | AY24: 5460-152-825 | AZ24: 신규발행
A25: 41 | B25: 479 | C25: 5460399647 | D25: - - | E25: N | F25: 본사 | G25: 20260331 | H25: ZH | I25: K04709 | J25: 주식회사 디비하이텍 | L25: JEONG/HOYONG | N25: / / | O25: 박지운 | P25: 한연지 | S25: 20260402 | T25: SZX/ICN | U25: 심천/인천 | V25: AMADEUS | W25: 중국 | X25: CHN | Y25: 중국 | Z25: SZX | AA25: 심천 | AB25: VI433692******1581 | AC25: 18602804 | AD25: 192300 | AE25: 300 | AF25: 200 | AG25: 0 | AH25: 192600 | AI25: 0 | AJ25: 192600 | AK25: 0 | AL25: 0 | AM25: 0 | AN25: 0 | AO25: 0 | AP25: / / | AR25: 4 | AS25: 0 | AT25: 8461 | AU25: 7690 | AV25: 17601704 | AW25: 2026/03/31 | AX25: 771 | AY25: 5460-152-826 | AZ25: 신규발행
A26: 42 | B26: 180 | C26: 5460450044 | D26: - - | E26: N | F26: 본사 | G26: 20260401 | H26: KE | I26: K04709 | J26: 주식회사 디비하이텍 | K26: 김희진 | L26: KIM/HEEJIN | N26: 1979/01/28 | O26: 박지운 | P26: 한연지 | S26: 20260408 | T26: ICN/TPE/ICN | U26: 인천/타이베이/인천 | V26: AMADEUS | W26: 동남아시아 | X26: TWN | Y26: 타이완 | Z26: TPE | AA26: 타이베이 | AB26: VI433692******1581 | AC26: 13602804 | AD26: 598300 | AE26: 161800 | AF26: 114000 | AG26: 0 | AH26: 760100 | AI26: 643800 | AJ26: 116300 | AK26: 643800 | AL26: 0 | AM26: 0 | AN26: 0 | AO26: 0 | AP26: / / | AR26: 4 | AS26: 0 | AT26: 24380 | AU26: 22160 | AV26: 14602804 | AW26: 2026/04/01 | AX26: 2220 | AY26: - - | AZ26: 신규발행
A27: 43 | B27: 180 | C27: 5460450046 | D27: - - | E27: N | F27: 본사 | G27: 20260401 | H27: KE | I27: K04709 | J27: 주식회사 디비하이텍 | K27: 이종래 | L27: LEE/JONGRAE | N27: 1980/10/13 | O27: 박지운 | P27: 한연지 | S27: 20260408 | T27: ICN/TPE/ICN | U27: 인천/타이베이/인천 | V27: AMADEUS | W27: 동남아시아 | X27: TWN | Y27: 타이완 | Z27: TPE | AA27: 타이베이 | AB27: VI433692******1581 | AC27: 19601804 | AD27: 598300 | AE27: 161800 | AF27: 114000 | AG27: 0 | AH27: 760100 | AI27: 643800 | AJ27: 116300 | AK27: 643800 | AL27: 0 | AM27: 0 | AN27: 0 | AO27: 0 | AP27: / / | AR27: 4 | AS27: 0 | AT27: 24380 | AU27: 22160 | AV27: 15602804 | AW27: 2026/04/01 | AX27: 2220 | AY27: - - | AZ27: 신규발행
A28: 44 | B28: 180 | C28: 5460450047 | D28: - - | E28: N | F28: 본사 | G28: 20260401 | H28: KE | I28: K04709 | J28: 주식회사 디비하이텍 | K28: 박정태 | L28: PARK/JEONGTAE | N28: 1973/01/15 | O28: 박지운 | P28: 한연지 | S28: 20260408 | T28: ICN/TPE/ICN | U28: 인천/타이베이/인천 | V28: AMADEUS | W28: 동남아시아 | X28: TWN | Y28: 타이완 | Z28: TPE | AA28: 타이베이 | AB28: VI433692******1581 | AC28: 11602804 | AD28: 598300 | AE28: 161800 | AF28: 114000 | AG28: 0 | AH28: 760100 | AI28: 643800 | AJ28: 116300 | AK28: 643800 | AL28: 0 | AM28: 0 | AN28: 0 | AO28: 0 | AP28: / / | AR28: 4 | AS28: 0 | AT28: 24380 | AU28: 22160 | AV28: 16602804 | AW28: 2026/04/01 | AX28: 2220 | AY28: - - | AZ28: 신규발행
A29: 48 | B29: 180 | C29: 5460450240 | D29: - - | E29: N | F29: 본사 | G29: 20260401 | H29: KE | I29: K04709 | J29: 주식회사 디비하이텍 | K29: 윤추실 | L29: YIN/QIUSHI | N29: 1996/11/13 | O29: 박지운 | P29: 한연지 | S29: 20260403 | T29: CAN/ICN | U29: 광저우(광주)/인천 | V29: AMADEUS | W29: 중국 | X29: CHN | Y29: 중국 | Z29: CAN | AA29: 광저우(광주) | AD29: 0 | AE29: 0 | AF29: 0 | AG29: 0 | AH29: 0 | AI29: 0 | AJ29: 0 | AK29: 0 | AL29: 0 | AM29: 0 | AN29: 0 | AO29: 0 | AP29: / / | AR29: 0 | AS29: 0 | AT29: 0 | AU29: 0 | AX29: 0 | AY29: 5460-330-185 | AZ29: 신규발행
A30: 56 | B30: 180 | C30: 9297591150 | D30: - - | E30: N | F30: 본사 | G30: 20260406 | H30: KE | I30: K04709 | J30: 주식회사 디비하이텍 | K30: 이상태 | L30: LEE/SANGTAE | N30: 1976/09/01 | O30: 박지운 | P30: 한연지 | S30: 20260413 | T30: ICN/SZX/ICN | U30: 인천/심천/인천 | V30: AMADEUS | W30: 중국 | X30: CHN | Y30: 중국 | Z30: SZX | AA30: 심천 | AB30: VI433692******1581 | AC30: 20603304 | AD30: 1006900 | AE30: 199900 | AF30: 156000 | AG30: 0 | AH30: 1206800 | AI30: 1206800 | AJ30: 0 | AK30: 1206800 | AL30: 0 | AM30: 0 | AN30: 0 | AO30: 0 | AP30: / / | AR30: 4 | AS30: 0 | AT30: 44303 | AU30: 40280 | AV30: 21603304 | AW30: 2026/04/06 | AX30: 4023 | AY30: - - | AZ30: 신규발행
AJ34: 결제금액 | AK34: =SUM(AH:AH)-SUM(AJ26:AJ28) -> 34650500
AJ35: 취소금액 | AK35: =-(AM19+AM22) -> -9456700
AJ36: 취급수수료 | AK36: =SUM(AT:AT) -> 1392042
AJ37: 취급수수료 취소 | AK37: =-(AT19+AT21+AT22) -> -727628
AJ39: 총계 | AK39: =SUM(AK34:AK37) -> 25858214
AJ41: * 법인카드 미반영 1건 : 5월 명세서 반영예정

Sheet 하나카드 결제내역
A1: NO | B1: 그룹번호 | C1: 카드번호 | D1: 이용일 | E1: 가맹점명 | F1: 이용원금 | G1: 할인금액 | H1: 이용 구분 | I1: 취소 여부 | J1: 할부 기간 | K1: 청구 회차 | L1: 결제금액 | M1: 수수료 | N1: 환가료 | O1: 결제후 잔액
A2: 57 | B2: 300003 | C2: 4336-****-****-1581 | D2: 2026.03.16 | E2: (주)세중나모여행_이니시스_취급수수료 | F2: 19668 | G2: 0 | H2: 국내일시불 | I2: N | J2: 0 | K2: 0 | L2: 19668 | M2: 0 | N2: 0 | O2: 0
A3: 58 | B3: 300003 | C3: 4336-****-****-1581 | D3: 2026.03.16 | E3: (주)세중나모여행_이니시스_취급수수료 | F3: 19668 | G3: 0 | H3: 국내일시불 | I3: N | J3: 0 | K3: 0 | L3: 19668 | M3: 0 | N3: 0 | O3: 0
A4: 59 | B4: 300003 | C4: 4336-****-****-1581 | D4: 2026.03.16 | E4: (주)세중나모여행_이니시스_취급수수료 | F4: 19668 | G4: 0 | H4: 국내일시불 | I4: N | J4: 0 | K4: 0 | L4: 19668 | M4: 0 | N4: 0 | O4: 0
A5: 60 | B5: 300003 | C5: 4336-****-****-1581 | D5: 2026.03.16 | E5: 중국국제항공공사한국지점BSP | F5: 541100 | G5: 0 | H5: 국내일시불 | I5: N | J5: 0 | K5: 0 | L5: 541100 | M5: 0 | N5: 0 | O5: 0
A6: 61 | B6: 300003 | C6: 4336-****-****-1581 | D6: 2026.03.16 | E6: 중국국제항공공사한국지점BSP | F6: 541100 | G6: 0 | H6: 국내일시불 | I6: N | J6: 0 | K6: 0 | L6: 541100 | M6: 0 | N6: 0 | O6: 0
A7: 62 | B7: 300003 | C7: 4336-****-****-1581 | D7: 2026.03.16 | E7: 중국국제항공공사한국지점BSP | F7: 541100 | G7: 0 | H7: 국내일시불 | I7: N | J7: 0 | K7: 0 | L7: 541100 | M7: 0 | N7: 0 | O7: 0
A8: 63 | B8: 300003 | C8: 4336-****-****-1581 | D8: 2026.03.17 | E8: (주)세중나모여행_이니시스_취급수수료 | F8: 38451 | G8: 0 | H8: 국내일시불 | I8: N | J8: 0 | K8: 0 | L8: 38451 | M8: 0 | N8: 0 | O8: 0
A9: 64 | B9: 300003 | C9: 4336-****-****-1581 | D9: 2026.03.17 | E9: 대한항공주식회사BSP | F9: 964200 | G9: 0 | H9: 국내일시불 | I9: N | J9: 0 | K9: 0 | L9: 964200 | M9: 0 | N9: 0 | O9: 0
A10: 65 | B10: 300003 | C10: 4336-****-****-1581 | D10: 2026.03.19 | E10: (주)세중나모여행_이니시스_취급수수료 | F10: 21164 | G10: 0 | H10: 국내일시불 | I10: N | J10: 0 | K10: 0 | L10: 21164 | M10: 0 | N10: 0 | O10: 0
A11: 66 | B11: 300003 | C11: 4336-****-****-1581 | D11: 2026.03.19 | E11: 중국동방항공비에스피 | F11: 496200 | G11: 0 | H11: 국내일시불 | I11: N | J11: 0 | K11: 0 | L11: 496200 | M11: 0 | N11: 0 | O11: 0
A12: 67 | B12: 300003 | C12: 4336-****-****-1581 | D12: 2026.03.20 | E12: (주)세중나모여행_이니시스_취급수수료 | F12: 24684 | G12: 0 | H12: 국내일시불 | I12: N | J12: 0 | K12: 0 | L12: 24684 | M12: 0 | N12: 0 | O12: 0
A13: 68 | B13: 300003 | C13: 4336-****-****-1581 | D13: 2026.03.20 | E13: 중국동방항공비에스피 | F13: 24400 | G13: 0 | H13: 국내일시불 | I13: N | J13: 0 | K13: 0 | L13: 24400 | M13: 0 | N13: 0 | O13: 0
... A55: 110 | B55: 300003 | C55: 4336-****-****-1581 | D55: 2026.04.06 | E55: 대한항공주식회사BSP | F55: 1206800 | G55: 0 | H55: 국내일시불 | I55: N | J55: 0 | K55: 0 | L55: 1206800 | M55: 0 | N55: 0 | O55: 0
A56: 총 합계 | F56: =SUM(F2:F55) -> 25858214 | L56: =SUM(L2:L55) -> 25858214
A57: 이하 여백 (End of document)
A58: 조회일시: 2026-04-15 14:48:38

Sheet 영문국문명
A1: 영문성 | B1: 영문명 | C1: 사번 | D1: 영문명 | E1: 국문명 | F1: 부서명(CC) | L1: 2025.12 조직개편 | P1: 2026.03 조직개편
A2: LEE | B2: HYUN JU | C2: 20000001 | D2: =A2&"/"&B2 -> LEE/HYUN JU | E2: =VLOOKUP(C2,'[1]사번,소속,이름'!$A$1:$C$159,3,) -> 이현주 | F2: SCM담당 | H2: SCM담당 | L2: =VLOOKUP($C2,[2]Sheet1!$A$2:$L$208,12,0) -> SCM담당 | M2: =VLOOKUP($C2,[2]Sheet1!$A$2:$L$208,2,0) -> 이현주 | N2: =VLOOKUP($C2,[2]Sheet1!$A$2:$L$208,11,0) -> 기술사무 | P2: =VLOOKUP($C2,[3]Sheet1!$A$2:$L$209,12,0) -> SCM담당 | Q2: =VLOOKUP($C2,[3]Sheet1!$A$2:$L$209,2,0) -> 이현주 | R2: =VLOOKUP($C2,[3]Sheet1!$A$2:$L$209,11,0) -> 기술사무
A3: DO | B3: BOK SOON | C3: 20000002 | D3: =A3&"/"&B3 -> DO/BOK SOON | E3: =VLOOKUP(C3,'[1]사번,소속,이름'!$A$1:$C$159,3,) -> 도복순 | F3: SCM담당 | H3: SCM담당 | L3: =VLOOKUP($C3,[2]Sheet1!$A$2:$L$208,12,0) -> SCM담당 | M3: =VLOOKUP($C3,[2]Sheet1!$A$2:$L$208,2,0) -> 도복순 | N3: =VLOOKUP($C3,[2]Sheet1!$A$2:$L$208,11,0) -> 기술사무 | P3: =VLOOKUP($C3,[3]Sheet1!$A$2:$L$209,12,0) -> SCM담당 | Q3: =VLOOKUP($C3,[3]Sheet1!$A$2:$L$209,2,0) -> 도복순 | R3: =VLOOKUP($C3,[3]Sheet1!$A$2:$L$209,11,0) -> 기술사무
A4: RHO | B4: SANG GYUN | C4: 20000003 | D4: =A4&"/"&B4 -> RHO/SANG GYUN | E4: =VLOOKUP(C4,'[1]사번,소속,이름'!$A$1:$C$159,3,) -> 노상균 | F4: Test팀 | H4: Test팀 | L4: =VLOOKUP($C4,[2]Sheet1!$A$2:$L$208,12,0) -> Test팀 | M4: =VLOOKUP($C4,[2]Sheet1!$A$2:$L$208,2,0) -> 노상균 | N4: =VLOOKUP($C4,[2]Sheet1!$A$2:$L$208,11,0) -> 기술사무 | P4: =VLOOKUP($C4,[3]Sheet1!$A$2:$L$209,12,0) -> Test팀 | Q4: =VLOOKUP($C4,[3]Sheet1!$A$2:$L$209,2,0) -> 노상균 | R4: =VLOOKUP($C4,[3]Sheet1!$A$2:$L$209,11,0) -> 기술사무
A5: KANG | B5: JUNGHO | C5: 20000004 | D5: =A5&"/"&B5 -> KANG/JUNGHO | E5: =VLOOKUP(C5,'[1]사번,소속,이름'!$A$1:$C$159,3,) -> 강정호 | F5: #N/A | H5: 자문역_임원 | L5: =VLOOKUP($C5,[2]Sheet1!$A$2:$L$208,12,0) -> 자문역 | M5: =VLOOKUP($C5,[2]Sheet1!$A$2:$L$208,2,0) -> 강정호 | N5: =VLOOKUP($C5,[2]Sheet1!$A$2:$L$208,11,0) -> 임원 | P5: =VLOOKUP($C5,[3]Sheet1!$A$2:$L$209,12,0) -> #N/A | Q5: =VLOOKUP($C5,[3]Sheet1!$A$2:$L$209,2,0) -> #N/A | R5: =VLOOKUP($C5,[3]Sheet1!$A$2:$L$209,11,0) -> #N/A
A6: CHOI | B6: JUNGMIN | C6: 20000005 | D6: =A6&"/"&B6 -> CHOI/JUNGMIN | E6: =VLOOKUP(C6,'[1]사번,소속,이름'!$A$1:$C$159,3,) -> 최정민 | F6: SCM담당_임원 | H6: SCM담당_임원 | L6: =VLOOKUP($C6,[2]Sheet1!$A$2:$L$208,12,0) -> SCM담당 | M6: =VLOOKUP($C6,[2]Sheet1!$A$2:$L$208,2,0) -> 최정민 | N6: =VLOOKUP($C6,[2]Sheet1!$A$2:$L$208,11,0) -> 임원 | P6: =VLOOKUP($C6,[3]Sheet1!$A$2:$L$209,12,0) -> SCM담당 | Q6: =VLOOKUP($C6,[3]Sheet1!$A$2:$L$209,2,0) -> 최정민 | R6: =VLOOKUP($C6,[3]Sheet1!$A$2:$L$209,11,0) -> 임원
A7: PARK | B7: TAE YONG | C7: 20000006 | D7: =A7&"/"&B7 -> PARK/TAE YONG | E7: =VLOOKUP(C7,'[1]사번,소속,이름'!$A$1:$C$159,3,) -> 박태용 | F7: 품질팀 | H7: 품질팀 | L7: =VLOOKUP($C7,[2]Sheet1!$A$2:$L$208,12,0) -> 품질팀 | M7: =VLOOKUP($C7,[2]Sheet1!$A$2:$L$208,2,0) -> 박태용 | N7: =VLOOKUP($C7,[2]Sheet1!$A$2:$L$208,11,0) -> 기술사무 | P7: =VLOOKUP($C7,[3]Sheet1!$A$2:$L$209,12,0) -> 품질팀 | Q7: =VLOOKUP($C7,[3]Sheet1!$A$2:$L$209,2,0) -> 박태용 | R7: =VLOOKUP($C7,[3]Sheet1!$A$2:$L$209,11,0) -> 기술사무
A8: LEE | B8: DO HUN | C8: 20000007 | D8: =A8&"/"&B8 -> LEE/DO HUN | E8: =VLOOKUP(C8,'[1]사번,소속,이름'!$A$1:$C$159,3,) -> 이도훈 | F8: Test팀 | H8: Test팀 | L8: =VLOOKUP($C8,[2]Sheet1!$A$2:$L$208,12,0) -> Test팀 | M8: =VLOOKUP($C8,[2]Sheet1!$A$2:$L$208,2,0) -> 이도훈 | N8: =VLOOKUP($C8,[2]Sheet1!$A$2:$L$208,11,0) -> 기술사무 | P8: =VLOOKUP($C8,[3]Sheet1!$A$2:$L$209,12,0) -> Test팀 | Q8: =VLOOKUP($C8,[3]Sheet1!$A$2:$L$209,2,0) -> 이도훈 | R8: =VLOOKUP($C8,[3]Sheet1!$A$2:$L$209,11,0) -> 기술사무
A9: SO | B9: SUN MAN | C9: 20000008 | D9: =A9&"/"&B9 -> SO/SUN MAN | E9: =VLOOKUP(C9,'[1]사번,소속,이름'!$A$1:$C$159,3,) -> 소순만 | F9: 제품기술팀 | H9: 제품기술팀 | L9: =VLOOKUP($C9,[2]Sheet1!$A$2:$L$208,12,0) -> 제품기술팀 | M9: =VLOOKUP($C9,[2]Sheet1!$A$2:$L$208,2,0) -> 소순만 | N9: =VLOOKUP($C9,[2]Sheet1!$A$2:$L$208,11,0) -> 기술사무 | P9: =VLOOKUP($C9,[3]Sheet1!$A$2:$L$209,12,0) -> 제품기술팀 | Q9: =VLOOKUP($C9,[3]Sheet1!$A$2:$L$209,2,0) -> 소순만 | R9: =VLOOKUP($C9,[3]Sheet1!$A$2:$L$209,11,0) -> 기술사무
A10: KWON | B10: YOUSUK | C10: 20000010 | D10: =A10&"/"&B10 -> KWON/YOUSUK | E10: =VLOOKUP(C10,'[1]사번,소속,이름'!$A$1:$C$159,3,) -> 권유석 | F10: 심천지사 | H10: 심천지사 | L10: =VLOOKUP($C10,[2]Sheet1!$A$2:$L$208,12,0) -> 심천지사 | M10: =VLOOKUP($C10,[2]Sheet1!$A$2:$L$208,2,0) -> 권유석 | N10: =VLOOKUP($C10,[2]Sheet1!$A$2:$L$208,11,0) -> 기술사무 | P10: =VLOOKUP($C10,[3]Sheet1!$A$2:$L$209,12,0) -> 심천지사 | Q10: =VLOOKUP($C10,[3]Sheet1!$A$2:$L$209,2,0) -> 권유석 | R10: =VLOOKUP($C10,[3]Sheet1!$A$2:$L$209,11,0) -> 기술사무
A11: JU | B11: YANG JUNG | C11: 20000013 | D11: =A11&"/"&B11 -> JU/YANG JUNG | E11: =VLOOKUP(C11,'[1]사번,소속,이름'!$A$1:$C$159,3,) -> 주양중 | F11: IT파트 | H11: IT파트 | L11: =VLOOKUP($C11,[2]Sheet1!$A$2:$L$208,12,0) -> IT파트 | M11: =VLOOKUP($C11,[2]Sheet1!$A$2:$L$208,2,0) -> 주양중 | N11: =VLOOKUP($C11,[2]Sheet1!$A$2:$L$208,11,0) -> 기술사무 | P11: =VLOOKUP($C11,[3]Sheet1!$A$2:$L$209,12,0) -> IT파트 | Q11: =VLOOKUP($C11,[3]Sheet1!$A$2:$L$209,2,0) -> 주양중 | R11: =VLOOKUP($C11,[3]Sheet1!$A$2:$L$209,11,0) -> 기술사무
A12: HUH | B12: SE HWA | C12: 20000014 | D12: =A12&"/"&B12 -> HUH/SE HWA | E12: =VLOOKUP(C12,'[1]사번,소속,이름'!$A$1:$C$159,3,) -> 허세화 | F12: 외주생산파트 | H12: 외주생산파트 | L12: =VLOOKUP($C12,[2]Sheet1!$A$2:$L$208,12,0) -> 외주생산파트 | M12: =VLOOKUP($C12,[2]Sheet1!$A$2:$L$208,2,0) -> 허세화 | N12: =VLOOKUP($C12,[2]Sheet1!$A$2:$L$208,11,0) -> 기술사무 | P12: =VLOOKUP($C12,[3]Sheet1!$A$2:$L$209,12,0) -> 외주생산파트 | Q12: =VLOOKUP($C12,[3]Sheet1!$A$2:$L$209,2,0) -> 허세화 | R12: =VLOOKUP($C12,[3]Sheet1!$A$2:$L$209,11,0) -> 기술사무
A13: SUNG | B13: EUN JOO | C13: 20000015 | D13: =A13&"/"&B13 -> SUNG/EUN JOO | E13: =VLOOKUP(C13,'[1]사번,소속,이름'!$A$1:$C$159,3,) -> 성은주 | F13: 외주생산파트 | H13: 외주생산파트 | L13: =VLOOKUP($C13,[2]Sheet1!$A$2:$L$208,12,0) -> 외주생산파트 | M13: =VLOOKUP($C13,[2]Sheet1!$A$2:$L$208,2,0) -> 성은주 | N13: =VLOOKUP($C13,[2]Sheet1!$A$2:$L$208,11,0) -> 기술사무 | P13: =VLOOKUP($C13,[3]Sheet1!$A$2:$L$209,12,0) -> 외주생산파트 | Q13: =VLOOKUP($C13,[3]Sheet1!$A$2:$L$209,2,0) -> 성은주 | R13: =VLOOKUP($C13,[3]Sheet1!$A$2:$L$209,11,0) -> 기술사무
A14: AN | B14: JOO HEE | C14: 20000016 | D14: =A14&"/"&B14 -> AN/JOO HEE | E14: =VLOOKUP(C14,'[1]사번,소속,이름'!$A$1:$C$159,3,) -> 안주희 | F14: 외주생산파트 | H14: 외주생산파트 | L14: =VLOOKUP($C14,[2]Sheet1!$A$2:$L$208,12,0) -> 외주생산파트 | M14: =VLOOKUP($C14,[2]Sheet1!$A$2:$L$208,2,0) -> 안주희 | N14: =VLOOKUP($C14,[2]Sheet1!$A$2:$L$208,11,0) -> 기술사무 | P14: =VLOOKUP($C14,[3]Sheet1!$A$2:$L$209,12,0) -> 외주생산파트 | Q14: =VLOOKUP($C14,[3]Sheet1!$A$2:$L$209,2,0) -> 안주희 | R14: =VLOOKUP($C14,[3]Sheet1!$A$2:$L$209,11,0) -> 기술사무
A15: KIM | B15: HYUNIL | C15: 20000017 | D15: =A15&"/"&B15 -> KIM/HYUNIL | E15: =VLOOKUP(C15,'[1]사번,소속,이름'!$A$1:$C$159,3,) -> 김현일 | F15: 전략구매파트 | H15: 전략구매파트 | L15: =VLOOKUP($C15,[2]Sheet1!$A$2:$L$208,12,0) -> 전략구매파트 | M15: =VLOOKUP($C15,[2]Sheet1!$A$2:$L$208,2,0) -> 김현일 | N15: =VLOOKUP($C15,[2]Sheet1!$A$2:$L$208,11,0) -> 기술사무 | P15: =VLOOKUP($C15,[3]Sheet1!$A$2:$L$209,12,0) -> 전략구매파트 | Q15: =VLOOKUP($C15,[3]Sheet1!$A$2:$L$209,2,0) -> 김현일 | R15: =VLOOKUP($C15,[3]Sheet1!$A$2:$L$209,11,0) -> 기술사무
A16: PARK | B16: YU BE | C16: 20000018 | D16: =A16&"/"&B16 -> PARK/YU BE | E16: =VLOOKUP(C16,'[1]사번,소속,이름'!$A$1:$C$159,3,) -> 박유배 | F16: 제품기술팀 | H16: 제품기술팀 | L16: =VLOOKUP($C16,[2]Sheet1!$A$2:$L$208,12,0) -> 제품기술팀 | M16: =VLOOKUP($C16,[2]Sheet1!$A$2:$L$208,2,0) -> 박유배 | N16: =VLOOKUP($C16,[2]Sheet1!$A$2:$L$208,11,0) -> 기술사무 | P16: =VLOOKUP($C16,[3]Sheet1!$A$2:$L$209,12,0) -> 제품기술팀 | Q16: =VLOOKUP($C16,[3]Sheet1!$A$2:$L$209,2,0) -> 박유배 | R16: =VLOOKUP($C16,[3]Sheet1!$A$2:$L$209,11,0) -> 기술사무
A17: PARK | B17: JEONG TAE | C17: 20000019 | D17: =A17&"/"&B17 -> PARK/JEONG TAE | E17: =VLOOKUP(C17,'[1]사번,소속,이름'!$A$1:$C$159,3,) -> 박정태 | F17: 기술지원담당_임원 | H17: 기술지원담당_임원 | L17: =VLOOKUP($C17,[2]Sheet1!$A$2:$L$208,12,0) -> 기술지원담당 | M17: =VLOOKUP($C17,[2]Sheet1!$A$2:$L$208,2,0) -> 박정태 | N17: =VLOOKUP($C17,[2]Sheet1!$A$2:$L$208,11,0) -> 임원 | P17: =VLOOKUP($C17,[3]Sheet1!$A$2:$L$209,12,0) -> 기술지원담당 | Q17: =VLOOKUP($C17,[3]Sheet1!$A$2:$L$209,2,0) -> 박정태 | R17: =VLOOKUP($C17,[3]Sheet1!$A$2:$L$209,11,0) -> 임원
... A53: SONG | B53: SI YEON | C53: 20000064 | D53: =A53&"/"&B53 -> SONG/SI YEON | E53: =VLOOKUP(C53,'[1]사번,소속,이름'!$A$1:$C$159,3,) -> 송시연 | F53: Layout팀 | H53: Layout팀 | L53: =VLOOKUP($C53,[2]Sheet1!$A$2:$L$208,12,0) -> Layout팀 | M53: =VLOOKUP($C53,[2]Sheet1!$A$2:$L$208,2,0) -> 송시연 | N53: =VLOOKUP($C53,[2]Sheet1!$A$2:$L$208,11,0) -> 기술사무 | P53: =VLOOKUP($C53,[3]Sheet1!$A$2:$L$209,12,0) -> Layout팀 | Q53: =VLOOKUP($C53,[3]Sheet1!$A$2:$L$209,2,0) -> 송시연 | R53: =VLOOKUP($C53,[3]Sheet1!$A$2:$L$209,11,0) -> 기술사무
A54: HWANG | B54: CHAN GYU | C54: 20000065 | D54: =A54&"/"&B54 -> HWANG/CHAN GYU | E54: =VLOOKUP(C54,'[1]사번,소속,이름'!$A$1:$C$159,3,) -> 황찬규 | F54: #N/A | H54: Layout팀 | L54: =VLOOKUP($C54,[2]Sheet1!$A$2:$L$208,12,0) -> Layout팀 | M54: =VLOOKUP($C54,[2]Sheet1!$A$2:$L$208,2,0) -> 황찬규 | N54: =VLOOKUP($C54,[2]Sheet1!$A$2:$L$208,11,0) -> 기술사무 | P54: =VLOOKUP($C54,[3]Sheet1!$A$2:$L$209,12,0) -> #N/A | Q54: =VLOOKUP($C54,[3]Sheet1!$A$2:$L$209,2,0) -> #N/A | R54: =VLOOKUP($C54,[3]Sheet1!$A$2:$L$209,11,0) -> #N/A
A55: CHOI | B55: SU IM | C55: 20000067 | D55: =A55&"/"&B55 -> CHOI/SU IM | E55: =VLOOKUP(C55,'[1]사번,소속,이름'!$A$1:$C$159,3,) -> 최수임 | F55: 영업팀 | H55: 영업팀 | L55: =VLOOKUP($C55,[2]Sheet1!$A$2:$L$208,12,0) -> 영업팀 | M55: =VLOOKUP($C55,[2]Sheet1!$A$2:$L$208,2,0) -> 최수임 | N55: =VLOOKUP($C55,[2]Sheet1!$A$2:$L$208,11,0) -> 기술사무 | P55: =VLOOKUP($C55,[3]Sheet1!$A$2:$L$209,12,0) -> 영업팀 | Q55: =VLOOKUP($C55,[3]Sheet1!$A$2:$L$209,2,0) -> 최수임 | R55: =VLOOKUP($C55,[3]Sheet1!$A$2:$L$209,11,0) -> 기술사무
A56: BAN | B56: KI HWAN | C56: 20000068 | D56: =A56&"/"&B56 -> BAN/KI HWAN | E56: =VLOOKUP(C56,'[1]사번,소속,이름'!$A$1:$C$159,3,) -> 반기환 | F56: Test팀 | H56: Test팀 | L56: =VLOOKUP($C56,[2]Sheet1!$A$2:$L$208,12,0) -> Test팀 | M56: =VLOOKUP($C56,[2]Sheet1!$A$2:$L$208,2,0) -> 반기환 | N56: =VLOOKUP($C56,[2]Sheet1!$A$2:$L$208,11,0) -> 기술사무 | P56: =VLOOKUP($C56,[3]Sheet1!$A$2:$L$209,12,0) -> Test팀 | Q56: =VLOOKUP($C56,[3]Sheet1!$A$2:$L$209,2,0) -> 반기환 | R56: =VLOOKUP($C56,[3]Sheet1!$A$2:$L$209,11,0) -> 기술사무
A57: PARK | B57: YONGJUN | C57: 20000069 | D57: =A57&"/"&B57 -> PARK/YONGJUN | E57: =VLOOKUP(C57,'[1]사번,소속,이름'!$A$1:$C$159,3,) -> 박용준 | F57: 품질팀 | H57: 품질팀 | L57: =VLOOKUP($C57,[2]Sheet1!$A$2:$L$208,12,0) -> 품질팀 | M57: =VLOOKUP($C57,[2]Sheet1!$A$2:$L$208,2,0) -> 박용준 | N57: =VLOOKUP($C57,[2]Sheet1!$A$2:$L$208,11,0) -> 기술사무 | P57: =VLOOKUP($C57,[3]Sheet1!$A$2:$L$209,12,0) -> 품질팀 | Q57: =VLOOKUP($C57,[3]Sheet1!$A$2:$L$209,2,0) -> 박용준 | R57: =VLOOKUP($C57,[3]Sheet1!$A$2:$L$209,11,0) -> 기술사무
A58: OH | B58: TAK JUN | C58: 20000071 | D58: =A58&"/"&B58 -> OH/TAK JUN | E58: =VLOOKUP(C58,'[1]사번,소속,이름'!$A$1:$C$159,3,) -> 오택준 | F58: Interface파트 | H58: DDI개발1팀 | L58: =VLOOKUP($C58,[2]Sheet1!$A$2:$L$208,12,0) -> Interface파트(1팀) | M58: =VLOOKUP($C58,[2]Sheet1!$A$2:$L$208,2,0) -> 오택준 | N58: =VLOOKUP($C58,[2]Sheet1!$A$2:$L$208,11,0) -> 기술사무 | P58: =VLOOKUP($C58,[3]Sheet1!$A$2:$L$209,12,0) -> Interface파트 | Q58: =VLOOKUP($C58,[3]Sheet1!$A$2:$L$209,2,0) -> 오택준 | R58: =VLOOKUP($C58,[3]Sheet1!$A$2:$L$209,11,0) -> 기술사무
A59: HWANG | B59: YOUNG JU | C59: 20000072 | D59: =A59&"/"&B59 -> HWANG/YOUNG JU | E59: =VLOOKUP(C59,'[1]사번,소속,이름'!$A$1:$C$159,3,) -> 황영주 | F59: Interface파트 | H59: DDI개발1팀 | L59: =VLOOKUP($C59,[2]Sheet1!$A$2:$L$208,12,0) -> Interface파트(1팀) | M59: =VLOOKUP($C59,[2]Sheet1!$A$2:$L$208,2,0) -> 황영주 | N59: =VLOOKUP($C59,[2]Sheet1!$A$2:$L$208,11,0) -> 기술사무 | P59: =VLOOKUP($C59,[3]Sheet1!$A$2:$L$209,12,0) -> Interface파트 | Q59: =VLOOKUP($C59,[3]Sheet1!$A$2:$L$209,2,0) -> 황영주 | R59: =VLOOKUP($C59,[3]Sheet1!$A$2:$L$209,11,0) -> 기술사무
A60: LEE | B60: KWAN JOO | C60: 20000073 | D60: =A60&"/"&B60 -> LEE/KWAN JOO | E60: =VLOOKUP(C60,'[1]사번,소속,이름'!$A$1:$C$159,3,) -> 이관주 | F60: 제품개발1파트 | H60: DDI개발1팀 | L60: =VLOOKUP($C60,[2]Sheet1!$A$2:$L$208,12,0) -> Logic파트(1팀) | M60: =VLOOKUP($C60,[2]Sheet1!$A$2:$L$208,2,0) -> 이관주 | N60: =VLOOKUP($C60,[2]Sheet1!$A$2:$L$208,11,0) -> 기술사무 | P60: =VLOOKUP($C60,[3]Sheet1!$A$2:$L$209,12,0) -> 제품개발1파트 | Q60: =VLOOKUP($C60,[3]Sheet1!$A$2:$L$209,2,0) -> 이관주 | R60: =VLOOKUP($C60,[3]Sheet1!$A$2:$L$209,11,0) -> 기술사무
A61: SEO | B61: JUNGIL | C61: 20000074 | D61: =A61&"/"&B61 -> SEO/JUNGIL | E61: =VLOOKUP(C61,'[1]사번,소속,이름'!$A$1:$C$159,3,) -> 서정일 | F61: 제품개발1파트 | H61: DDI개발1팀 | L61: =VLOOKUP($C61,[2]Sheet1!$A$2:$L$208,12,0) -> Logic파트(1팀) | M61: =VLOOKUP($C61,[2]Sheet1!$A$2:$L$208,2,0) -> 서정일 | N61: =VLOOKUP($C61,[2]Sheet1!$A$2:$L$208,11,0) -> 기술사무 | P61: =VLOOKUP($C61,[3]Sheet1!$A$2:$L$209,12,0) -> 제품개발1파트 | Q61: =VLOOKUP($C61,[3]Sheet1!$A$2:$L$209,2,0) -> 서정일 | R61: =VLOOKUP($C61,[3]Sheet1!$A$2:$L$209,11,0) -> 기술사무
A62: YU | B62: MYOUNG SEOK | C62: 20000076 | D62: =A62&"/"&B62 -> YU/MYOUNG SEOK | E62: =VLOOKUP(C62,'[1]사번,소속,이름'!$A$1:$C$159,3,) -> 유명석 | F62: Logic파트 | H62: DDI개발2팀 | L62: =VLOOKUP($C62,[2]Sheet1!$A$2:$L$208,12,0) -> Logic파트(2팀) | M62: =VLOOKUP($C62,[2]Sheet1!$A$2:$L$208,2,0) -> 유명석 | N62: =VLOOKUP($C62,[2]Sheet1!$A$2:$L$208,11,0) -> 기술사무 | P62: =VLOOKUP($C62,[3]Sheet1!$A$2:$L$209,12,0) -> Logic파트 | Q62: =VLOOKUP($C62,[3]Sheet1!$A$2:$L$209,2,0) -> 유명석 | R62: =VLOOKUP($C62,[3]Sheet1!$A$2:$L$209,11,0) -> 기술사무
A63: SEOL | B63: HYUN SOO | C63: 20000078 | D63: =A63&"/"&B63 -> SEOL/HYUN SOO | E63: =VLOOKUP(C63,'[1]사번,소속,이름'!$A$1:$C$159,3,) -> 설현수 | F63: Layout팀 | H63: Layout팀 | L63: =VLOOKUP($C63,[2]Sheet1!$A$2:$L$208,12,0) -> Layout팀 | M63: =VLOOKUP($C63,[2]Sheet1!$A$2:$L$208,2,0) -> 설현수 | N63: =VLOOKUP($C63,[2]Sheet1!$A$2:$L$208,11,0) -> 기술사무 | P63: =VLOOKUP($C63,[3]Sheet1!$A$2:$L$209,12,0) -> Layout팀 | Q63: =VLOOKUP($C63,[3]Sheet1!$A$2:$L$209,2,0) -> 설현수 | R63: =VLOOKUP($C63,[3]Sheet1!$A$2:$L$209,11,0) -> 기술사무
A64: MA | B64: PYUNG SIK | C64: 20000079 | D64: =A64&"/"&B64 -> MA/PYUNG SIK | E64: =VLOOKUP(C64,'[1]사번,소속,이름'!$A$1:$C$159,3,) -> 마평식 | F64: Analog1파트 | H64: DDI개발1팀 | L64: =VLOOKUP($C64,[2]Sheet1!$A$2:$L$208,12,0) -> Analog파트(1팀) | M64: =VLOOKUP($C64,[2]Sheet1!$A$2:$L$208,2,0) -> 마평식 | N64: =VLOOKUP($C64,[2]Sheet1!$A$2:$L$208,11,0) -> 기술사무 | P64: =VLOOKUP($C64,[3]Sheet1!$A$2:$L$209,12,0) -> Analog1파트 | Q64: =VLOOKUP($C64,[3]Sheet1!$A$2:$L$209,2,0) -> 마평식 | R64: =VLOOKUP($C64,[3]Sheet1!$A$2:$L$209,11,0) -> 기술사무
A65: PARK | B65: CHEONWI | C65: 20000081 | D65: =A65&"/"&B65 -> PARK/CHEONWI | E65: =VLOOKUP(C65,'[1]사번,소속,이름'!$A$1:$C$159,3,) -> 박천위 | F65: Analog1파트 | H65: DDI개발1팀 | L65: =VLOOKUP($C65,[2]Sheet1!$A$2:$L$208,12,0) -> Analog파트(1팀) | M65: =VLOOKUP($C65,[2]Sheet1!$A$2:$L$208,2,0) -> 박천위 | N65: =VLOOKUP($C65,[2]Sheet1!$A$2:$L$208,11,0) -> 기술사무 | P65: =VLOOKUP($C65,[3]Sheet1!$A$2:$L$209,12,0) -> Analog1파트 | Q65: =VLOOKUP($C65,[3]Sheet1!$A$2:$L$209,2,0) -> 박천위 | R65: =VLOOKUP($C65,[3]Sheet1!$A$2:$L$209,11,0) -> 기술사무
A66: YIN | B66: QIUSHI | C66: 20000082 | D66: =A66&"/"&B66 -> YIN/QIUSHI | E66: =VLOOKUP(C66,'[1]사번,소속,이름'!$A$1:$C$159,3,) -> 윤추실 | F66: 제품기술팀 | H66: 제품기술팀 | L66: =VLOOKUP($C66,[2]Sheet1!$A$2:$L$208,12,0) -> 제품기술팀 | M66: =VLOOKUP($C66,[2]Sheet1!$A$2:$L$208,2,0) -> 윤추실 | N66: =VLOOKUP($C66,[2]Sheet1!$A$2:$L$208,11,0) -> 기술사무 | P66: =VLOOKUP($C66,[3]Sheet1!$A$2:$L$209,12,0) -> 제품기술팀 | Q66: =VLOOKUP($C66,[3]Sheet1!$A$2:$L$209,2,0) -> 윤추실 | R66: =VLOOKUP($C66,[3]Sheet1!$A$2:$L$209,11,0) -> 기술사무
... A85: LIM | B85: NA YOUNG | C85: 20000104 | D85: =A85&"/"&B85 -> LIM/NA YOUNG | E85: =VLOOKUP(C85,'[1]사번,소속,이름'!$A$1:$C$159,3,) -> 임나영 | F85: 피플팀 | H85: 피플팀 | L85: =VLOOKUP($C85,[2]Sheet1!$A$2:$L$208,12,0) -> 피플팀 | M85: =VLOOKUP($C85,[2]Sheet1!$A$2:$L$208,2,0) -> 임나영 | N85: =VLOOKUP($C85,[2]Sheet1!$A$2:$L$208,11,0) -> 기술사무 | P85: =VLOOKUP($C85,[3]Sheet1!$A$2:$L$209,12,0) -> 피플팀 | Q85: =VLOOKUP($C85,[3]Sheet1!$A$2:$L$209,2,0) -> 임나영 | R85: =VLOOKUP($C85,[3]Sheet1!$A$2:$L$209,11,0) -> 기술사무
A86: KIM | B86: KWANG SOO | C86: 20000107 | D86: =A86&"/"&B86 -> KIM/KWANG SOO | E86: =VLOOKUP(C86,'[1]사번,소속,이름'!$A$1:$C$159,3,) -> 김광수 | F86: #N/A | H86: 경영지원실_임원 | L86: =VLOOKUP($C86,[2]Sheet1!$A$2:$L$208,12,0) -> 경영지원실 | M86: =VLOOKUP($C86,[2]Sheet1!$A$2:$L$208,2,0) -> 김광수 | N86: =VLOOKUP($C86,[2]Sheet1!$A$2:$L$208,11,0) -> 임원 | P86: =VLOOKUP($C86,[3]Sheet1!$A$2:$L$209,12,0) -> #N/A | Q86: =VLOOKUP($C86,[3]Sheet1!$A$2:$L$209,2,0) -> #N/A | R86: =VLOOKUP($C86,[3]Sheet1!$A$2:$L$209,11,0) -> #N/A
A87: KIM | B87: SUNG BEEN | C87: 20000108 | D87: =A87&"/"&B87 -> KIM/SUNG BEEN | E87: =VLOOKUP(C87,'[1]사번,소속,이름'!$A$1:$C$159,3,) -> 김성빈 | F87: #N/A | H87: Layout팀 | L87: =VLOOKUP($C87,[2]Sheet1!$A$2:$L$208,12,0) -> Layout팀 | M87: =VLOOKUP($C87,[2]Sheet1!$A$2:$L$208,2,0) -> 김성빈 | N87: =VLOOKUP($C87,[2]Sheet1!$A$2:$L$208,11,0) -> 기술사무 | P87: =VLOOKUP($C87,[3]Sheet1!$A$2:$L$209,12,0) -> #N/A | Q87: =VLOOKUP($C87,[3]Sheet1!$A$2:$L$209,2,0) -> #N/A | R87: =VLOOKUP($C87,[3]Sheet1!$A$2:$L$209,11,0) -> #N/A
A88: Shin | B88: Hyun Jin | C88: 20000109 | D88: =A88&"/"&B88 -> Shin/Hyun Jin | E88: =VLOOKUP(C88,'[1]사번,소속,이름'!$A$1:$C$159,3,) -> 신현진 | F88: Layout팀 | H88: Layout팀 | L88: =VLOOKUP($C88,[2]Sheet1!$A$2:$L$208,12,0) -> Layout팀 | M88: =VLOOKUP($C88,[2]Sheet1!$A$2:$L$208,2,0) -> 신현진 | N88: =VLOOKUP($C88,[2]Sheet1!$A$2:$L$208,11,0) -> 기술사무 | P88: =VLOOKUP($C88,[3]Sheet1!$A$2:$L$209,12,0) -> Layout팀 | Q88: =VLOOKUP($C88,[3]Sheet1!$A$2:$L$209,2,0) -> 신현진 | R88: =VLOOKUP($C88,[3]Sheet1!$A$2:$L$209,11,0) -> 기술사무
A89: KIM | B89: HEE JOON | C89: 20000111 | D89: =A89&"/"&B89 -> KIM/HEE JOON | E89: =VLOOKUP(C89,'[1]사번,소속,이름'!$A$1:$C$159,3,) -> 김희준 | F89: Analog1파트 | H89: DDI개발1팀 | L89: =VLOOKUP($C89,[2]Sheet1!$A$2:$L$208,12,0) -> Analog파트(1팀) | M89: =VLOOKUP($C89,[2]Sheet1!$A$2:$L$208,2,0) -> 김희준 | N89: =VLOOKUP($C89,[2]Sheet1!$A$2:$L$208,11,0) -> 기술사무 | P89: =VLOOKUP($C89,[3]Sheet1!$A$2:$L$209,12,0) -> Analog1파트 | Q89: =VLOOKUP($C89,[3]Sheet1!$A$2:$L$209,2,0) -> 김희준 | R89: =VLOOKUP($C89,[3]Sheet1!$A$2:$L$209,11,0) -> 기술사무
A90: LEE | B90: JANG HYUN | C90: 20000112 | D90: =A90&"/"&B90 -> LEE/JANG HYUN | E90: =VLOOKUP(C90,'[1]사번,소속,이름'!$A$1:$C$159,3,) -> 이장현 | F90: 전략구매파트 | H90: 전략구매파트 | L90: =VLOOKUP($C90,[2]Sheet1!$A$2:$L$208,12,0) -> 전략구매파트 | M90: =VLOOKUP($C90,[2]Sheet1!$A$2:$L$208,2,0) -> 이장현 | N90: =VLOOKUP($C90,[2]Sheet1!$A$2:$L$208,11,0) -> 기술사무 | P90: =VLOOKUP($C90,[3]Sheet1!$A$2:$L$209,12,0) -> 전략구매파트 | Q90: =VLOOKUP($C90,[3]Sheet1!$A$2:$L$209,2,0) -> 이장현 | R90: =VLOOKUP($C90,[3]Sheet1!$A$2:$L$209,11,0) -> 기술사무
A91: YANG | B91: WOO SUN | C91: 20000114 | D91: =A91&"/"&B91 -> YANG/WOO SUN | E91: =VLOOKUP(C91,'[1]사번,소속,이름'!$A$1:$C$159,3,) -> 양우선 | F91: Logic파트 | H91: DDI개발1팀 | L91: =VLOOKUP($C91,[2]Sheet1!$A$2:$L$208,12,0) -> Logic파트(1팀) | M91: =VLOOKUP($C91,[2]Sheet1!$A$2:$L$208,2,0) -> 양우선 | N91: =VLOOKUP($C91,[2]Sheet1!$A$2:$L$208,11,0) -> 기술사무 | P91: =VLOOKUP($C91,[3]Sheet1!$A$2:$L$209,12,0) -> Logic파트 | Q91: =VLOOKUP($C91,[3]Sheet1!$A$2:$L$209,2,0) -> 양우선 | R91: =VLOOKUP($C91,[3]Sheet1!$A$2:$L$209,11,0) -> 기술사무
A92: KYOUNG | B92: MYEONG GEUN | C92: 20000116 | D92: =A92&"/"&B92 -> KYOUNG/MYEONG GEUN | E92: =VLOOKUP(C92,'[1]사번,소속,이름'!$A$1:$C$159,3,) -> 경명근 | F92: Layout팀 | H92: Layout팀 | L92: =VLOOKUP($C92,[2]Sheet1!$A$2:$L$208,12,0) -> Layout팀 | M92: =VLOOKUP($C92,[2]Sheet1!$A$2:$L$208,2,0) -> 경명근 | N92: =VLOOKUP($C92,[2]Sheet1!$A$2:$L$208,11,0) -> 기술사무 | P92: =VLOOKUP($C92,[3]Sheet1!$A$2:$L$209,12,0) -> Layout팀 | Q92: =VLOOKUP($C92,[3]Sheet1!$A$2:$L$209,2,0) -> 경명근 | R92: =VLOOKUP($C92,[3]Sheet1!$A$2:$L$209,11,0) -> 기술사무
A93: KIM | B93: SOOMIN | C93: 20000117 | D93: =A93&"/"&B93 -> KIM/SOOMIN | E93: =VLOOKUP(C93,'[1]사번,소속,이름'!$A$1:$C$159,3,) -> 김수민 | F93: 재무관리팀 | H93: 재무관리팀 | L93: =VLOOKUP($C93,[2]Sheet1!$A$2:$L$208,12,0) -> 재무관리팀 | M93: =VLOOKUP($C93,[2]Sheet1!$A$2:$L$208,2,0) -> 김수민 | N93: =VLOOKUP($C93,[2]Sheet1!$A$2:$L$208,11,0) -> 기술사무 | P93: =VLOOKUP($C93,[3]Sheet1!$A$2:$L$209,12,0) -> 재무관리팀 | Q93: =VLOOKUP($C93,[3]Sheet1!$A$2:$L$209,2,0) -> 김수민 | R93: =VLOOKUP($C93,[3]Sheet1!$A$2:$L$209,11,0) -> 기술사무
...

Sheet 사번소속이름
A1: 사원번호 | B1: 부서명 | C1: 이름
A3: 20000001 | B3: SCM팀 | C3: 이현주
A4: 20000002 | B4: SCM팀 | C4: 도복순
A5: 20000003 | B5: Test팀 | C5: 노상균
A6: 20000004 | B6: 사업담당 | C6: 강정호
A7: 20000005 | B7: SCM팀 | C7: 최정민
A8: 20000006 | B8: 품질팀 | C8: 박태용
A9: 20000007 | B9: Test팀 | C9: 이도훈
A10: 20000008 | B10: 제품기술팀 | C10: 소순만
A11: 20000009 | B11: Test팀 | C11: 이돈수
A12: 20000010 | B12: 영업팀 | C12: 권유석
A13: 20000013 | B13: IT파트 | C13: 주양중
... A159: 20000176 | B159: 설계2팀 | C159: 강의진
A160: 20000177
A161: 20000178
A162: 20000179
A163: 20000180
A164: 20000181
A165: 20000182
A166: 20000183
A167: 20000184
A168: 20000185
A169: 20000186
A170: 20000187
A171: 20000188
... A210: 20000227
A211: 20000228 | B211: DDI마케팅파트 | C211: 이동매
